[2022-08-18 15:13:36,654] {taskinstance.py:1032} INFO - Dependencies all met for <TaskInstance: zones_taxi_data_ingest.local_to_gcs_task manual__2022-08-18T15:13:33.997399+00:00 [queued]>
[2022-08-18 15:13:36,662] {taskinstance.py:1032} INFO - Dependencies all met for <TaskInstance: zones_taxi_data_ingest.local_to_gcs_task manual__2022-08-18T15:13:33.997399+00:00 [queued]>
[2022-08-18 15:13:36,662] {taskinstance.py:1238} INFO - 
--------------------------------------------------------------------------------
[2022-08-18 15:13:36,662] {taskinstance.py:1239} INFO - Starting attempt 1 of 1
[2022-08-18 15:13:36,662] {taskinstance.py:1240} INFO - 
--------------------------------------------------------------------------------
[2022-08-18 15:13:36,673] {taskinstance.py:1259} INFO - Executing <Task(PythonOperator): local_to_gcs_task> on 2022-08-18 15:13:33.997399+00:00
[2022-08-18 15:13:36,679] {standard_task_runner.py:52} INFO - Started process 18777 to run task
[2022-08-18 15:13:36,682] {standard_task_runner.py:76} INFO - Running: ['***', 'tasks', 'run', 'zones_taxi_data_ingest', 'local_to_gcs_task', 'manual__2022-08-18T15:13:33.997399+00:00', '--job-id', '138', '--raw', '--subdir', 'DAGS_FOLDER/zones_data_ingest.py', '--cfg-path', '/tmp/tmpkh0s4pjb', '--error-file', '/tmp/tmpv_zq8s2n']
[2022-08-18 15:13:36,682] {standard_task_runner.py:77} INFO - Job 138: Subtask local_to_gcs_task
[2022-08-18 15:13:36,726] {logging_mixin.py:109} INFO - Running <TaskInstance: zones_taxi_data_ingest.local_to_gcs_task manual__2022-08-18T15:13:33.997399+00:00 [running]> on host 18f0cb155a4e
[2022-08-18 15:13:36,766] {taskinstance.py:1426} INFO - Exporting the following env vars:
AIRFLOW_CTX_DAG_OWNER=***
AIRFLOW_CTX_DAG_ID=zones_taxi_data_ingest
AIRFLOW_CTX_TASK_ID=local_to_gcs_task
AIRFLOW_CTX_EXECUTION_DATE=2022-08-18T15:13:33.997399+00:00
AIRFLOW_CTX_DAG_RUN_ID=manual__2022-08-18T15:13:33.997399+00:00
[2022-08-18 15:13:36,774] {taskinstance.py:1700} ERROR - Task failed with exception
Traceback (most recent call last):
  File "/home/airflow/.local/lib/python3.7/site-packages/airflow/models/taskinstance.py", line 1329, in _run_raw_task
    self._execute_task_with_callbacks(context)
  File "/home/airflow/.local/lib/python3.7/site-packages/airflow/models/taskinstance.py", line 1455, in _execute_task_with_callbacks
    result = self._execute_task(context, self.task)
  File "/home/airflow/.local/lib/python3.7/site-packages/airflow/models/taskinstance.py", line 1511, in _execute_task
    result = execute_callable(context=context)
  File "/home/airflow/.local/lib/python3.7/site-packages/airflow/operators/python.py", line 174, in execute
    return_value = self.execute_callable()
  File "/home/airflow/.local/lib/python3.7/site-packages/airflow/operators/python.py", line 185, in execute_callable
    return self.python_callable(*self.op_args, **self.op_kwargs)
  File "/opt/airflow/dags/zones_data_ingest.py", line 54, in upload_to_gcs
    blob.upload_from_filename(local_file)
  File "/home/airflow/.local/lib/python3.7/site-packages/google/cloud/storage/blob.py", line 2720, in upload_from_filename
    with open(filename, "rb") as file_obj:
FileNotFoundError: [Errno 2] No such file or directory: '/opt/airflow/zones.parquet'
[2022-08-18 15:13:36,785] {taskinstance.py:1277} INFO - Marking task as FAILED. dag_id=zones_taxi_data_ingest, task_id=local_to_gcs_task, execution_date=20220818T151333, start_date=20220818T151336, end_date=20220818T151336
[2022-08-18 15:13:36,796] {standard_task_runner.py:92} ERROR - Failed to execute job 138 for task local_to_gcs_task
Traceback (most recent call last):
  File "/home/airflow/.local/lib/python3.7/site-packages/airflow/task/task_runner/standard_task_runner.py", line 85, in _start_by_fork
    args.func(args, dag=self.dag)
  File "/home/airflow/.local/lib/python3.7/site-packages/airflow/cli/cli_parser.py", line 48, in command
    return func(*args, **kwargs)
  File "/home/airflow/.local/lib/python3.7/site-packages/airflow/utils/cli.py", line 92, in wrapper
    return f(*args, **kwargs)
  File "/home/airflow/.local/lib/python3.7/site-packages/airflow/cli/commands/task_command.py", line 298, in task_run
    _run_task_by_selected_method(args, dag, ti)
  File "/home/airflow/.local/lib/python3.7/site-packages/airflow/cli/commands/task_command.py", line 107, in _run_task_by_selected_method
    _run_raw_task(args, ti)
  File "/home/airflow/.local/lib/python3.7/site-packages/airflow/cli/commands/task_command.py", line 184, in _run_raw_task
    error_file=args.error_file,
  File "/home/airflow/.local/lib/python3.7/site-packages/airflow/utils/session.py", line 70, in wrapper
    return func(*args, session=session, **kwargs)
  File "/home/airflow/.local/lib/python3.7/site-packages/airflow/models/taskinstance.py", line 1329, in _run_raw_task
    self._execute_task_with_callbacks(context)
  File "/home/airflow/.local/lib/python3.7/site-packages/airflow/models/taskinstance.py", line 1455, in _execute_task_with_callbacks
    result = self._execute_task(context, self.task)
  File "/home/airflow/.local/lib/python3.7/site-packages/airflow/models/taskinstance.py", line 1511, in _execute_task
    result = execute_callable(context=context)
  File "/home/airflow/.local/lib/python3.7/site-packages/airflow/operators/python.py", line 174, in execute
    return_value = self.execute_callable()
  File "/home/airflow/.local/lib/python3.7/site-packages/airflow/operators/python.py", line 185, in execute_callable
    return self.python_callable(*self.op_args, **self.op_kwargs)
  File "/opt/airflow/dags/zones_data_ingest.py", line 54, in upload_to_gcs
    blob.upload_from_filename(local_file)
  File "/home/airflow/.local/lib/python3.7/site-packages/google/cloud/storage/blob.py", line 2720, in upload_from_filename
    with open(filename, "rb") as file_obj:
FileNotFoundError: [Errno 2] No such file or directory: '/opt/airflow/zones.parquet'
[2022-08-18 15:13:36,814] {local_task_job.py:154} INFO - Task exited with return code 1
[2022-08-18 15:13:36,843] {local_task_job.py:264} INFO - 0 downstream tasks scheduled from follow-on schedule check
