[2022-08-18 09:24:22,278] {taskinstance.py:1032} INFO - Dependencies all met for <TaskInstance: yellow_taxi_data_ingest.bigquery_external_table_task scheduled__2019-01-01T01:00:00+00:00 [queued]>
[2022-08-18 09:24:22,287] {taskinstance.py:1032} INFO - Dependencies all met for <TaskInstance: yellow_taxi_data_ingest.bigquery_external_table_task scheduled__2019-01-01T01:00:00+00:00 [queued]>
[2022-08-18 09:24:22,287] {taskinstance.py:1238} INFO - 
--------------------------------------------------------------------------------
[2022-08-18 09:24:22,287] {taskinstance.py:1239} INFO - Starting attempt 1 of 2
[2022-08-18 09:24:22,288] {taskinstance.py:1240} INFO - 
--------------------------------------------------------------------------------
[2022-08-18 09:24:22,302] {taskinstance.py:1259} INFO - Executing <Task(BigQueryCreateExternalTableOperator): bigquery_external_table_task> on 2019-01-01 01:00:00+00:00
[2022-08-18 09:24:22,307] {standard_task_runner.py:52} INFO - Started process 5734 to run task
[2022-08-18 09:24:22,309] {standard_task_runner.py:76} INFO - Running: ['***', 'tasks', 'run', 'yellow_taxi_data_ingest', 'bigquery_external_table_task', 'scheduled__2019-01-01T01:00:00+00:00', '--job-id', '83', '--pool', 'default_pool', '--raw', '--subdir', 'DAGS_FOLDER/yellow_taxi_data_ingest_dag.py', '--cfg-path', '/tmp/tmpt0nejaan', '--error-file', '/tmp/tmpbiy3qs6n']
[2022-08-18 09:24:22,310] {standard_task_runner.py:77} INFO - Job 83: Subtask bigquery_external_table_task
[2022-08-18 09:24:22,355] {logging_mixin.py:109} INFO - Running <TaskInstance: yellow_taxi_data_ingest.bigquery_external_table_task scheduled__2019-01-01T01:00:00+00:00 [running]> on host 18f0cb155a4e
[2022-08-18 09:24:22,386] {warnings.py:110} WARNING - /home/***/.local/lib/python3.7/site-packages/***/utils/context.py:152: AirflowContextDeprecationWarning: Accessing 'execution_date' from the template is deprecated and will be removed in a future version. Please use 'data_interval_start' or 'logical_date' instead.
  warnings.warn(_create_deprecation_warning(key, self._deprecation_replacements[key]))

[2022-08-18 09:24:22,404] {taskinstance.py:1426} INFO - Exporting the following env vars:
AIRFLOW_CTX_DAG_OWNER=***
AIRFLOW_CTX_DAG_ID=yellow_taxi_data_ingest
AIRFLOW_CTX_TASK_ID=bigquery_external_table_task
AIRFLOW_CTX_EXECUTION_DATE=2019-01-01T01:00:00+00:00
AIRFLOW_CTX_DAG_RUN_ID=scheduled__2019-01-01T01:00:00+00:00
[2022-08-18 09:24:22,405] {crypto.py:82} WARNING - empty cryptography key - values will not be stored encrypted.
[2022-08-18 09:24:23,228] {taskinstance.py:1700} ERROR - Task failed with exception
Traceback (most recent call last):
  File "/home/airflow/.local/lib/python3.7/site-packages/airflow/models/taskinstance.py", line 1329, in _run_raw_task
    self._execute_task_with_callbacks(context)
  File "/home/airflow/.local/lib/python3.7/site-packages/airflow/models/taskinstance.py", line 1455, in _execute_task_with_callbacks
    result = self._execute_task(context, self.task)
  File "/home/airflow/.local/lib/python3.7/site-packages/airflow/models/taskinstance.py", line 1511, in _execute_task
    result = execute_callable(context=context)
  File "/home/airflow/.local/lib/python3.7/site-packages/airflow/providers/google/cloud/operators/bigquery.py", line 1196, in execute
    table_resource=self.table_resource,
  File "/home/airflow/.local/lib/python3.7/site-packages/airflow/providers/google/common/hooks/base_google.py", line 430, in inner_wrapper
    return func(self, *args, **kwargs)
  File "/home/airflow/.local/lib/python3.7/site-packages/airflow/providers/google/cloud/hooks/bigquery.py", line 408, in create_empty_table
    table=table, exists_ok=exists_ok, retry=retry
  File "/home/airflow/.local/lib/python3.7/site-packages/google/cloud/bigquery/client.py", line 755, in create_table
    timeout=timeout,
  File "/home/airflow/.local/lib/python3.7/site-packages/google/cloud/bigquery/client.py", line 782, in _call_api
    return call()
  File "/home/airflow/.local/lib/python3.7/site-packages/google/api_core/retry.py", line 291, in retry_wrapped_func
    on_error=on_error,
  File "/home/airflow/.local/lib/python3.7/site-packages/google/api_core/retry.py", line 189, in retry_target
    return target()
  File "/home/airflow/.local/lib/python3.7/site-packages/google/cloud/_http.py", line 484, in api_request
    raise exceptions.from_http_response(response)
google.api_core.exceptions.BadRequest: 400 POST https://bigquery.googleapis.com/bigquery/v2/projects/polynomial-land/datasets/trips_data_all/tables?prettyPrint=false: Error while reading table: external_table, error message: Failed to expand table external_table with file pattern gs://dtc_data_lake_polynomial-land/raw//opt/airflow/yellow_tripdata_2019-01.parquet: matched no files. File: gs://dtc_data_lake_polynomial-land/raw//opt/airflow/yellow_tripdata_2019-01.parquet
[2022-08-18 09:24:23,238] {taskinstance.py:1277} INFO - Marking task as UP_FOR_RETRY. dag_id=yellow_taxi_data_ingest, task_id=bigquery_external_table_task, execution_date=20190101T010000, start_date=20220818T092422, end_date=20220818T092423
[2022-08-18 09:24:23,249] {standard_task_runner.py:92} ERROR - Failed to execute job 83 for task bigquery_external_table_task
Traceback (most recent call last):
  File "/home/airflow/.local/lib/python3.7/site-packages/airflow/task/task_runner/standard_task_runner.py", line 85, in _start_by_fork
    args.func(args, dag=self.dag)
  File "/home/airflow/.local/lib/python3.7/site-packages/airflow/cli/cli_parser.py", line 48, in command
    return func(*args, **kwargs)
  File "/home/airflow/.local/lib/python3.7/site-packages/airflow/utils/cli.py", line 92, in wrapper
    return f(*args, **kwargs)
  File "/home/airflow/.local/lib/python3.7/site-packages/airflow/cli/commands/task_command.py", line 298, in task_run
    _run_task_by_selected_method(args, dag, ti)
  File "/home/airflow/.local/lib/python3.7/site-packages/airflow/cli/commands/task_command.py", line 107, in _run_task_by_selected_method
    _run_raw_task(args, ti)
  File "/home/airflow/.local/lib/python3.7/site-packages/airflow/cli/commands/task_command.py", line 184, in _run_raw_task
    error_file=args.error_file,
  File "/home/airflow/.local/lib/python3.7/site-packages/airflow/utils/session.py", line 70, in wrapper
    return func(*args, session=session, **kwargs)
  File "/home/airflow/.local/lib/python3.7/site-packages/airflow/models/taskinstance.py", line 1329, in _run_raw_task
    self._execute_task_with_callbacks(context)
  File "/home/airflow/.local/lib/python3.7/site-packages/airflow/models/taskinstance.py", line 1455, in _execute_task_with_callbacks
    result = self._execute_task(context, self.task)
  File "/home/airflow/.local/lib/python3.7/site-packages/airflow/models/taskinstance.py", line 1511, in _execute_task
    result = execute_callable(context=context)
  File "/home/airflow/.local/lib/python3.7/site-packages/airflow/providers/google/cloud/operators/bigquery.py", line 1196, in execute
    table_resource=self.table_resource,
  File "/home/airflow/.local/lib/python3.7/site-packages/airflow/providers/google/common/hooks/base_google.py", line 430, in inner_wrapper
    return func(self, *args, **kwargs)
  File "/home/airflow/.local/lib/python3.7/site-packages/airflow/providers/google/cloud/hooks/bigquery.py", line 408, in create_empty_table
    table=table, exists_ok=exists_ok, retry=retry
  File "/home/airflow/.local/lib/python3.7/site-packages/google/cloud/bigquery/client.py", line 755, in create_table
    timeout=timeout,
  File "/home/airflow/.local/lib/python3.7/site-packages/google/cloud/bigquery/client.py", line 782, in _call_api
    return call()
  File "/home/airflow/.local/lib/python3.7/site-packages/google/api_core/retry.py", line 291, in retry_wrapped_func
    on_error=on_error,
  File "/home/airflow/.local/lib/python3.7/site-packages/google/api_core/retry.py", line 189, in retry_target
    return target()
  File "/home/airflow/.local/lib/python3.7/site-packages/google/cloud/_http.py", line 484, in api_request
    raise exceptions.from_http_response(response)
google.api_core.exceptions.BadRequest: 400 POST https://bigquery.googleapis.com/bigquery/v2/projects/polynomial-land/datasets/trips_data_all/tables?prettyPrint=false: Error while reading table: external_table, error message: Failed to expand table external_table with file pattern gs://dtc_data_lake_polynomial-land/raw//opt/airflow/yellow_tripdata_2019-01.parquet: matched no files. File: gs://dtc_data_lake_polynomial-land/raw//opt/airflow/yellow_tripdata_2019-01.parquet
[2022-08-18 09:24:23,284] {local_task_job.py:154} INFO - Task exited with return code 1
[2022-08-18 09:24:23,309] {local_task_job.py:264} INFO - 0 downstream tasks scheduled from follow-on schedule check
[2022-08-18 09:51:25,722] {taskinstance.py:1032} INFO - Dependencies all met for <TaskInstance: yellow_taxi_data_ingest.bigquery_external_table_task scheduled__2019-01-01T01:00:00+00:00 [queued]>
[2022-08-18 09:51:25,730] {taskinstance.py:1032} INFO - Dependencies all met for <TaskInstance: yellow_taxi_data_ingest.bigquery_external_table_task scheduled__2019-01-01T01:00:00+00:00 [queued]>
[2022-08-18 09:51:25,730] {taskinstance.py:1238} INFO - 
--------------------------------------------------------------------------------
[2022-08-18 09:51:25,730] {taskinstance.py:1239} INFO - Starting attempt 1 of 2
[2022-08-18 09:51:25,730] {taskinstance.py:1240} INFO - 
--------------------------------------------------------------------------------
[2022-08-18 09:51:25,741] {taskinstance.py:1259} INFO - Executing <Task(BigQueryCreateExternalTableOperator): bigquery_external_table_task> on 2019-01-01 01:00:00+00:00
[2022-08-18 09:51:25,745] {standard_task_runner.py:52} INFO - Started process 7052 to run task
[2022-08-18 09:51:25,748] {standard_task_runner.py:76} INFO - Running: ['***', 'tasks', 'run', 'yellow_taxi_data_ingest', 'bigquery_external_table_task', 'scheduled__2019-01-01T01:00:00+00:00', '--job-id', '94', '--pool', 'default_pool', '--raw', '--subdir', 'DAGS_FOLDER/yellow_taxi_data_ingest_dag.py', '--cfg-path', '/tmp/tmpitx31uid', '--error-file', '/tmp/tmpf19e1gvt']
[2022-08-18 09:51:25,748] {standard_task_runner.py:77} INFO - Job 94: Subtask bigquery_external_table_task
[2022-08-18 09:51:25,786] {logging_mixin.py:109} INFO - Running <TaskInstance: yellow_taxi_data_ingest.bigquery_external_table_task scheduled__2019-01-01T01:00:00+00:00 [running]> on host 18f0cb155a4e
[2022-08-18 09:51:25,812] {warnings.py:110} WARNING - /home/***/.local/lib/python3.7/site-packages/***/utils/context.py:152: AirflowContextDeprecationWarning: Accessing 'execution_date' from the template is deprecated and will be removed in a future version. Please use 'data_interval_start' or 'logical_date' instead.
  warnings.warn(_create_deprecation_warning(key, self._deprecation_replacements[key]))

[2022-08-18 09:51:25,830] {taskinstance.py:1426} INFO - Exporting the following env vars:
AIRFLOW_CTX_DAG_OWNER=***
AIRFLOW_CTX_DAG_ID=yellow_taxi_data_ingest
AIRFLOW_CTX_TASK_ID=bigquery_external_table_task
AIRFLOW_CTX_EXECUTION_DATE=2019-01-01T01:00:00+00:00
AIRFLOW_CTX_DAG_RUN_ID=scheduled__2019-01-01T01:00:00+00:00
[2022-08-18 09:51:25,831] {crypto.py:82} WARNING - empty cryptography key - values will not be stored encrypted.
[2022-08-18 09:51:26,518] {taskinstance.py:1700} ERROR - Task failed with exception
Traceback (most recent call last):
  File "/home/airflow/.local/lib/python3.7/site-packages/airflow/models/taskinstance.py", line 1329, in _run_raw_task
    self._execute_task_with_callbacks(context)
  File "/home/airflow/.local/lib/python3.7/site-packages/airflow/models/taskinstance.py", line 1455, in _execute_task_with_callbacks
    result = self._execute_task(context, self.task)
  File "/home/airflow/.local/lib/python3.7/site-packages/airflow/models/taskinstance.py", line 1511, in _execute_task
    result = execute_callable(context=context)
  File "/home/airflow/.local/lib/python3.7/site-packages/airflow/providers/google/cloud/operators/bigquery.py", line 1196, in execute
    table_resource=self.table_resource,
  File "/home/airflow/.local/lib/python3.7/site-packages/airflow/providers/google/common/hooks/base_google.py", line 430, in inner_wrapper
    return func(self, *args, **kwargs)
  File "/home/airflow/.local/lib/python3.7/site-packages/airflow/providers/google/cloud/hooks/bigquery.py", line 408, in create_empty_table
    table=table, exists_ok=exists_ok, retry=retry
  File "/home/airflow/.local/lib/python3.7/site-packages/google/cloud/bigquery/client.py", line 755, in create_table
    timeout=timeout,
  File "/home/airflow/.local/lib/python3.7/site-packages/google/cloud/bigquery/client.py", line 782, in _call_api
    return call()
  File "/home/airflow/.local/lib/python3.7/site-packages/google/api_core/retry.py", line 291, in retry_wrapped_func
    on_error=on_error,
  File "/home/airflow/.local/lib/python3.7/site-packages/google/api_core/retry.py", line 189, in retry_target
    return target()
  File "/home/airflow/.local/lib/python3.7/site-packages/google/cloud/_http.py", line 484, in api_request
    raise exceptions.from_http_response(response)
google.api_core.exceptions.BadRequest: 400 POST https://bigquery.googleapis.com/bigquery/v2/projects/polynomial-land/datasets/trips_data_all/tables?prettyPrint=false: Error while reading table: external_table, error message: Failed to expand table external_table with file pattern gs://dtc_data_lake_polynomial-land/raw/yellow_tripdata/2019-01//yellow_tripdata_2019-01.parquet: matched no files. File: gs://dtc_data_lake_polynomial-land/raw/yellow_tripdata/2019-01//yellow_tripdata_2019-01.parquet
[2022-08-18 09:51:26,536] {taskinstance.py:1277} INFO - Marking task as UP_FOR_RETRY. dag_id=yellow_taxi_data_ingest, task_id=bigquery_external_table_task, execution_date=20190101T010000, start_date=20220818T095125, end_date=20220818T095126
[2022-08-18 09:51:26,550] {standard_task_runner.py:92} ERROR - Failed to execute job 94 for task bigquery_external_table_task
Traceback (most recent call last):
  File "/home/airflow/.local/lib/python3.7/site-packages/airflow/task/task_runner/standard_task_runner.py", line 85, in _start_by_fork
    args.func(args, dag=self.dag)
  File "/home/airflow/.local/lib/python3.7/site-packages/airflow/cli/cli_parser.py", line 48, in command
    return func(*args, **kwargs)
  File "/home/airflow/.local/lib/python3.7/site-packages/airflow/utils/cli.py", line 92, in wrapper
    return f(*args, **kwargs)
  File "/home/airflow/.local/lib/python3.7/site-packages/airflow/cli/commands/task_command.py", line 298, in task_run
    _run_task_by_selected_method(args, dag, ti)
  File "/home/airflow/.local/lib/python3.7/site-packages/airflow/cli/commands/task_command.py", line 107, in _run_task_by_selected_method
    _run_raw_task(args, ti)
  File "/home/airflow/.local/lib/python3.7/site-packages/airflow/cli/commands/task_command.py", line 184, in _run_raw_task
    error_file=args.error_file,
  File "/home/airflow/.local/lib/python3.7/site-packages/airflow/utils/session.py", line 70, in wrapper
    return func(*args, session=session, **kwargs)
  File "/home/airflow/.local/lib/python3.7/site-packages/airflow/models/taskinstance.py", line 1329, in _run_raw_task
    self._execute_task_with_callbacks(context)
  File "/home/airflow/.local/lib/python3.7/site-packages/airflow/models/taskinstance.py", line 1455, in _execute_task_with_callbacks
    result = self._execute_task(context, self.task)
  File "/home/airflow/.local/lib/python3.7/site-packages/airflow/models/taskinstance.py", line 1511, in _execute_task
    result = execute_callable(context=context)
  File "/home/airflow/.local/lib/python3.7/site-packages/airflow/providers/google/cloud/operators/bigquery.py", line 1196, in execute
    table_resource=self.table_resource,
  File "/home/airflow/.local/lib/python3.7/site-packages/airflow/providers/google/common/hooks/base_google.py", line 430, in inner_wrapper
    return func(self, *args, **kwargs)
  File "/home/airflow/.local/lib/python3.7/site-packages/airflow/providers/google/cloud/hooks/bigquery.py", line 408, in create_empty_table
    table=table, exists_ok=exists_ok, retry=retry
  File "/home/airflow/.local/lib/python3.7/site-packages/google/cloud/bigquery/client.py", line 755, in create_table
    timeout=timeout,
  File "/home/airflow/.local/lib/python3.7/site-packages/google/cloud/bigquery/client.py", line 782, in _call_api
    return call()
  File "/home/airflow/.local/lib/python3.7/site-packages/google/api_core/retry.py", line 291, in retry_wrapped_func
    on_error=on_error,
  File "/home/airflow/.local/lib/python3.7/site-packages/google/api_core/retry.py", line 189, in retry_target
    return target()
  File "/home/airflow/.local/lib/python3.7/site-packages/google/cloud/_http.py", line 484, in api_request
    raise exceptions.from_http_response(response)
google.api_core.exceptions.BadRequest: 400 POST https://bigquery.googleapis.com/bigquery/v2/projects/polynomial-land/datasets/trips_data_all/tables?prettyPrint=false: Error while reading table: external_table, error message: Failed to expand table external_table with file pattern gs://dtc_data_lake_polynomial-land/raw/yellow_tripdata/2019-01//yellow_tripdata_2019-01.parquet: matched no files. File: gs://dtc_data_lake_polynomial-land/raw/yellow_tripdata/2019-01//yellow_tripdata_2019-01.parquet
[2022-08-18 09:51:26,562] {local_task_job.py:154} INFO - Task exited with return code 1
[2022-08-18 09:51:26,585] {local_task_job.py:264} INFO - 0 downstream tasks scheduled from follow-on schedule check
[2022-08-18 10:07:16,749] {taskinstance.py:1032} INFO - Dependencies all met for <TaskInstance: yellow_taxi_data_ingest.bigquery_external_table_task backfill__2019-01-01T01:00:00+00:00 [queued]>
[2022-08-18 10:07:16,756] {taskinstance.py:1032} INFO - Dependencies all met for <TaskInstance: yellow_taxi_data_ingest.bigquery_external_table_task backfill__2019-01-01T01:00:00+00:00 [queued]>
[2022-08-18 10:07:16,756] {taskinstance.py:1238} INFO - 
--------------------------------------------------------------------------------
[2022-08-18 10:07:16,756] {taskinstance.py:1239} INFO - Starting attempt 1 of 2
[2022-08-18 10:07:16,756] {taskinstance.py:1240} INFO - 
--------------------------------------------------------------------------------
[2022-08-18 10:07:16,767] {taskinstance.py:1259} INFO - Executing <Task(BigQueryCreateExternalTableOperator): bigquery_external_table_task> on 2019-01-01 01:00:00+00:00
[2022-08-18 10:07:16,771] {standard_task_runner.py:52} INFO - Started process 7884 to run task
[2022-08-18 10:07:16,773] {standard_task_runner.py:76} INFO - Running: ['***', 'tasks', 'run', 'yellow_taxi_data_ingest', 'bigquery_external_table_task', 'backfill__2019-01-01T01:00:00+00:00', '--job-id', '101', '--pool', 'default_pool', '--raw', '--subdir', 'DAGS_FOLDER/yellow_taxi_data_ingest_dag.py', '--cfg-path', '/tmp/tmpv8xwjeod', '--error-file', '/tmp/tmp9ydw5_6y']
[2022-08-18 10:07:16,774] {standard_task_runner.py:77} INFO - Job 101: Subtask bigquery_external_table_task
[2022-08-18 10:07:16,809] {logging_mixin.py:109} INFO - Running <TaskInstance: yellow_taxi_data_ingest.bigquery_external_table_task backfill__2019-01-01T01:00:00+00:00 [running]> on host 18f0cb155a4e
[2022-08-18 10:07:16,838] {warnings.py:110} WARNING - /home/***/.local/lib/python3.7/site-packages/***/utils/context.py:152: AirflowContextDeprecationWarning: Accessing 'execution_date' from the template is deprecated and will be removed in a future version. Please use 'data_interval_start' or 'logical_date' instead.
  warnings.warn(_create_deprecation_warning(key, self._deprecation_replacements[key]))

[2022-08-18 10:07:16,853] {taskinstance.py:1426} INFO - Exporting the following env vars:
AIRFLOW_CTX_DAG_OWNER=***
AIRFLOW_CTX_DAG_ID=yellow_taxi_data_ingest
AIRFLOW_CTX_TASK_ID=bigquery_external_table_task
AIRFLOW_CTX_EXECUTION_DATE=2019-01-01T01:00:00+00:00
AIRFLOW_CTX_DAG_RUN_ID=backfill__2019-01-01T01:00:00+00:00
[2022-08-18 10:07:16,854] {crypto.py:82} WARNING - empty cryptography key - values will not be stored encrypted.
[2022-08-18 10:07:17,479] {taskinstance.py:1277} INFO - Marking task as SUCCESS. dag_id=yellow_taxi_data_ingest, task_id=bigquery_external_table_task, execution_date=20190101T010000, start_date=20220818T100716, end_date=20220818T100717
[2022-08-18 10:07:17,507] {local_task_job.py:154} INFO - Task exited with return code 0
[2022-08-18 10:07:17,530] {local_task_job.py:264} INFO - 0 downstream tasks scheduled from follow-on schedule check
