{
 "cells": [
  {
   "cell_type": "code",
   "execution_count": 1,
   "id": "8a5805f1",
   "metadata": {},
   "outputs": [],
   "source": [
    "import pandas as pd"
   ]
  },
  {
   "cell_type": "code",
   "execution_count": 2,
   "id": "232f02b2",
   "metadata": {},
   "outputs": [],
   "source": [
    "from sqlalchemy import create_engine"
   ]
  },
  {
   "cell_type": "code",
   "execution_count": 3,
   "id": "cdfa7da3",
   "metadata": {},
   "outputs": [],
   "source": [
    "engine = create_engine('postgresql://root:root@localhost:5432/ny_taxi')"
   ]
  },
  {
   "cell_type": "code",
   "execution_count": 5,
   "id": "991c7e96",
   "metadata": {},
   "outputs": [
    {
     "name": "stdout",
     "output_type": "stream",
     "text": [
      "Unexpected exception formatting exception. Falling back to standard exception\n"
     ]
    },
    {
     "name": "stderr",
     "output_type": "stream",
     "text": [
      "Traceback (most recent call last):\n",
      "  File \"/home/kelan/.local/lib/python3.10/site-packages/sqlalchemy/engine/base.py\", line 3361, in _wrap_pool_connect\n",
      "    return fn()\n",
      "  File \"/home/kelan/.local/lib/python3.10/site-packages/sqlalchemy/pool/base.py\", line 310, in connect\n",
      "    return _ConnectionFairy._checkout(self)\n",
      "  File \"/home/kelan/.local/lib/python3.10/site-packages/sqlalchemy/pool/base.py\", line 868, in _checkout\n",
      "    fairy = _ConnectionRecord.checkout(pool)\n",
      "  File \"/home/kelan/.local/lib/python3.10/site-packages/sqlalchemy/pool/base.py\", line 476, in checkout\n",
      "    rec = pool._do_get()\n",
      "  File \"/home/kelan/.local/lib/python3.10/site-packages/sqlalchemy/pool/impl.py\", line 145, in _do_get\n",
      "    with util.safe_reraise():\n",
      "  File \"/home/kelan/.local/lib/python3.10/site-packages/sqlalchemy/util/langhelpers.py\", line 70, in __exit__\n",
      "    compat.raise_(\n",
      "  File \"/home/kelan/.local/lib/python3.10/site-packages/sqlalchemy/util/compat.py\", line 208, in raise_\n",
      "    raise exception\n",
      "  File \"/home/kelan/.local/lib/python3.10/site-packages/sqlalchemy/pool/impl.py\", line 143, in _do_get\n",
      "    return self._create_connection()\n",
      "  File \"/home/kelan/.local/lib/python3.10/site-packages/sqlalchemy/pool/base.py\", line 256, in _create_connection\n",
      "    return _ConnectionRecord(self)\n",
      "  File \"/home/kelan/.local/lib/python3.10/site-packages/sqlalchemy/pool/base.py\", line 371, in __init__\n",
      "    self.__connect()\n",
      "  File \"/home/kelan/.local/lib/python3.10/site-packages/sqlalchemy/pool/base.py\", line 665, in __connect\n",
      "    with util.safe_reraise():\n",
      "  File \"/home/kelan/.local/lib/python3.10/site-packages/sqlalchemy/util/langhelpers.py\", line 70, in __exit__\n",
      "    compat.raise_(\n",
      "  File \"/home/kelan/.local/lib/python3.10/site-packages/sqlalchemy/util/compat.py\", line 208, in raise_\n",
      "    raise exception\n",
      "  File \"/home/kelan/.local/lib/python3.10/site-packages/sqlalchemy/pool/base.py\", line 661, in __connect\n",
      "    self.dbapi_connection = connection = pool._invoke_creator(self)\n",
      "  File \"/home/kelan/.local/lib/python3.10/site-packages/sqlalchemy/engine/create.py\", line 578, in connect\n",
      "    return dialect.connect(*cargs, **cparams)\n",
      "  File \"/home/kelan/.local/lib/python3.10/site-packages/sqlalchemy/engine/default.py\", line 597, in connect\n",
      "    return self.dbapi.connect(*cargs, **cparams)\n",
      "  File \"/home/kelan/.local/lib/python3.10/site-packages/psycopg2/__init__.py\", line 122, in connect\n",
      "    conn = _connect(dsn, connection_factory=connection_factory, **kwasync)\n",
      "psycopg2.OperationalError: connection to server at \"localhost\" (127.0.0.1), port 5432 failed: Connection refused\n",
      "\tIs the server running on that host and accepting TCP/IP connections?\n",
      "\n",
      "\n",
      "The above exception was the direct cause of the following exception:\n",
      "\n",
      "Traceback (most recent call last):\n",
      "  File \"/home/kelan/.local/lib/python3.10/site-packages/IPython/core/interactiveshell.py\", line 3398, in run_code\n",
      "    exec(code_obj, self.user_global_ns, self.user_ns)\n",
      "  File \"/tmp/ipykernel_573/1831642854.py\", line 1, in <cell line: 1>\n",
      "    engine.connect()\n",
      "  File \"/home/kelan/.local/lib/python3.10/site-packages/sqlalchemy/engine/base.py\", line 3315, in connect\n",
      "    return self._connection_cls(self, close_with_result=close_with_result)\n",
      "  File \"/home/kelan/.local/lib/python3.10/site-packages/sqlalchemy/engine/base.py\", line 96, in __init__\n",
      "    else engine.raw_connection()\n",
      "  File \"/home/kelan/.local/lib/python3.10/site-packages/sqlalchemy/engine/base.py\", line 3394, in raw_connection\n",
      "    return self._wrap_pool_connect(self.pool.connect, _connection)\n",
      "  File \"/home/kelan/.local/lib/python3.10/site-packages/sqlalchemy/engine/base.py\", line 3364, in _wrap_pool_connect\n",
      "    Connection._handle_dbapi_exception_noconnection(\n",
      "  File \"/home/kelan/.local/lib/python3.10/site-packages/sqlalchemy/engine/base.py\", line 2198, in _handle_dbapi_exception_noconnection\n",
      "    util.raise_(\n",
      "  File \"/home/kelan/.local/lib/python3.10/site-packages/sqlalchemy/util/compat.py\", line 208, in raise_\n",
      "    raise exception\n",
      "  File \"/home/kelan/.local/lib/python3.10/site-packages/sqlalchemy/engine/base.py\", line 3361, in _wrap_pool_connect\n",
      "    return fn()\n",
      "  File \"/home/kelan/.local/lib/python3.10/site-packages/sqlalchemy/pool/base.py\", line 310, in connect\n",
      "    return _ConnectionFairy._checkout(self)\n",
      "  File \"/home/kelan/.local/lib/python3.10/site-packages/sqlalchemy/pool/base.py\", line 868, in _checkout\n",
      "    fairy = _ConnectionRecord.checkout(pool)\n",
      "  File \"/home/kelan/.local/lib/python3.10/site-packages/sqlalchemy/pool/base.py\", line 476, in checkout\n",
      "    rec = pool._do_get()\n",
      "  File \"/home/kelan/.local/lib/python3.10/site-packages/sqlalchemy/pool/impl.py\", line 145, in _do_get\n",
      "    with util.safe_reraise():\n",
      "  File \"/home/kelan/.local/lib/python3.10/site-packages/sqlalchemy/util/langhelpers.py\", line 70, in __exit__\n",
      "    compat.raise_(\n",
      "  File \"/home/kelan/.local/lib/python3.10/site-packages/sqlalchemy/util/compat.py\", line 208, in raise_\n",
      "    raise exception\n",
      "  File \"/home/kelan/.local/lib/python3.10/site-packages/sqlalchemy/pool/impl.py\", line 143, in _do_get\n",
      "    return self._create_connection()\n",
      "  File \"/home/kelan/.local/lib/python3.10/site-packages/sqlalchemy/pool/base.py\", line 256, in _create_connection\n",
      "    return _ConnectionRecord(self)\n",
      "  File \"/home/kelan/.local/lib/python3.10/site-packages/sqlalchemy/pool/base.py\", line 371, in __init__\n",
      "    self.__connect()\n",
      "  File \"/home/kelan/.local/lib/python3.10/site-packages/sqlalchemy/pool/base.py\", line 665, in __connect\n",
      "    with util.safe_reraise():\n",
      "  File \"/home/kelan/.local/lib/python3.10/site-packages/sqlalchemy/util/langhelpers.py\", line 70, in __exit__\n",
      "    compat.raise_(\n",
      "  File \"/home/kelan/.local/lib/python3.10/site-packages/sqlalchemy/util/compat.py\", line 208, in raise_\n",
      "    raise exception\n",
      "  File \"/home/kelan/.local/lib/python3.10/site-packages/sqlalchemy/pool/base.py\", line 661, in __connect\n",
      "    self.dbapi_connection = connection = pool._invoke_creator(self)\n",
      "  File \"/home/kelan/.local/lib/python3.10/site-packages/sqlalchemy/engine/create.py\", line 578, in connect\n",
      "    return dialect.connect(*cargs, **cparams)\n",
      "  File \"/home/kelan/.local/lib/python3.10/site-packages/sqlalchemy/engine/default.py\", line 597, in connect\n",
      "    return self.dbapi.connect(*cargs, **cparams)\n",
      "  File \"/home/kelan/.local/lib/python3.10/site-packages/psycopg2/__init__.py\", line 122, in connect\n",
      "    conn = _connect(dsn, connection_factory=connection_factory, **kwasync)\n",
      "sqlalchemy.exc.OperationalError: (psycopg2.OperationalError) connection to server at \"localhost\" (127.0.0.1), port 5432 failed: Connection refused\n",
      "\tIs the server running on that host and accepting TCP/IP connections?\n",
      "\n",
      "(Background on this error at: https://sqlalche.me/e/14/e3q8)\n",
      "\n",
      "During handling of the above exception, another exception occurred:\n",
      "\n",
      "Traceback (most recent call last):\n",
      "  File \"/home/kelan/.local/lib/python3.10/site-packages/executing/executing.py\", line 312, in executing\n",
      "    args = executing_cache[key]\n",
      "KeyError: (<code object run_code at 0x7f05129140e0, file \"/home/kelan/.local/lib/python3.10/site-packages/IPython/core/interactiveshell.py\", line 3362>, 139659763073248, 76)\n",
      "\n",
      "During handling of the above exception, another exception occurred:\n",
      "\n",
      "Traceback (most recent call last):\n",
      "  File \"/home/kelan/.local/lib/python3.10/site-packages/IPython/core/interactiveshell.py\", line 1993, in showtraceback\n",
      "    stb = self.InteractiveTB.structured_traceback(\n",
      "  File \"/home/kelan/.local/lib/python3.10/site-packages/IPython/core/ultratb.py\", line 1118, in structured_traceback\n",
      "    return FormattedTB.structured_traceback(\n",
      "  File \"/home/kelan/.local/lib/python3.10/site-packages/IPython/core/ultratb.py\", line 1012, in structured_traceback\n",
      "    return VerboseTB.structured_traceback(\n",
      "  File \"/home/kelan/.local/lib/python3.10/site-packages/IPython/core/ultratb.py\", line 865, in structured_traceback\n",
      "    formatted_exception = self.format_exception_as_a_whole(etype, evalue, etb, number_of_lines_of_context,\n",
      "  File \"/home/kelan/.local/lib/python3.10/site-packages/IPython/core/ultratb.py\", line 799, in format_exception_as_a_whole\n",
      "    self.get_records(etb, number_of_lines_of_context, tb_offset) if etb else []\n",
      "  File \"/home/kelan/.local/lib/python3.10/site-packages/IPython/core/ultratb.py\", line 854, in get_records\n",
      "    return list(stack_data.FrameInfo.stack_data(etb, options=options))[tb_offset:]\n",
      "  File \"/home/kelan/.local/lib/python3.10/site-packages/stack_data/core.py\", line 563, in stack_data\n",
      "    yield from collapse_repeated(\n",
      "  File \"/home/kelan/.local/lib/python3.10/site-packages/stack_data/utils.py\", line 84, in collapse_repeated\n",
      "    yield from map(mapper, original_group)\n",
      "  File \"/home/kelan/.local/lib/python3.10/site-packages/stack_data/core.py\", line 553, in mapper\n",
      "    return cls(f, options)\n",
      "  File \"/home/kelan/.local/lib/python3.10/site-packages/stack_data/core.py\", line 518, in __init__\n",
      "    self.executing = Source.executing(frame_or_tb)\n",
      "  File \"/home/kelan/.local/lib/python3.10/site-packages/executing/executing.py\", line 364, in executing\n",
      "    args = find(source=cls.for_frame(frame), retry_cache=True)\n",
      "  File \"/home/kelan/.local/lib/python3.10/site-packages/executing/executing.py\", line 247, in for_frame\n",
      "    return cls.for_filename(frame.f_code.co_filename, frame.f_globals or {}, use_cache)\n",
      "  File \"/home/kelan/.local/lib/python3.10/site-packages/executing/executing.py\", line 265, in for_filename\n",
      "    result = source_cache[filename] = cls._for_filename_and_lines(filename, lines)\n",
      "  File \"/home/kelan/.local/lib/python3.10/site-packages/executing/executing.py\", line 276, in _for_filename_and_lines\n",
      "    result = source_cache[(filename, lines)] = cls(filename, lines)\n",
      "  File \"/home/kelan/.local/lib/python3.10/site-packages/stack_data/core.py\", line 81, in __init__\n",
      "    self.asttokens()\n",
      "  File \"/home/kelan/.local/lib/python3.10/site-packages/executing/executing.py\", line 408, in asttokens\n",
      "    return ASTTokens(\n",
      "  File \"/home/kelan/.local/lib/python3.10/site-packages/asttokens/asttokens.py\", line 61, in __init__\n",
      "    source_text = six.ensure_text(source_text)\n",
      "AttributeError: module 'six' has no attribute 'ensure_text'\n"
     ]
    }
   ],
   "source": [
    "engine.connect()"
   ]
  },
  {
   "cell_type": "code",
   "execution_count": 6,
   "id": "ddc7aca7",
   "metadata": {},
   "outputs": [
    {
     "name": "stdout",
     "output_type": "stream",
     "text": [
      "Unexpected exception formatting exception. Falling back to standard exception\n"
     ]
    },
    {
     "name": "stderr",
     "output_type": "stream",
     "text": [
      "Traceback (most recent call last):\n",
      "  File \"/home/kelan/.local/lib/python3.10/site-packages/sqlalchemy/engine/base.py\", line 3361, in _wrap_pool_connect\n",
      "    return fn()\n",
      "  File \"/home/kelan/.local/lib/python3.10/site-packages/sqlalchemy/pool/base.py\", line 310, in connect\n",
      "    return _ConnectionFairy._checkout(self)\n",
      "  File \"/home/kelan/.local/lib/python3.10/site-packages/sqlalchemy/pool/base.py\", line 868, in _checkout\n",
      "    fairy = _ConnectionRecord.checkout(pool)\n",
      "  File \"/home/kelan/.local/lib/python3.10/site-packages/sqlalchemy/pool/base.py\", line 476, in checkout\n",
      "    rec = pool._do_get()\n",
      "  File \"/home/kelan/.local/lib/python3.10/site-packages/sqlalchemy/pool/impl.py\", line 145, in _do_get\n",
      "    with util.safe_reraise():\n",
      "  File \"/home/kelan/.local/lib/python3.10/site-packages/sqlalchemy/util/langhelpers.py\", line 70, in __exit__\n",
      "    compat.raise_(\n",
      "  File \"/home/kelan/.local/lib/python3.10/site-packages/sqlalchemy/util/compat.py\", line 208, in raise_\n",
      "    raise exception\n",
      "  File \"/home/kelan/.local/lib/python3.10/site-packages/sqlalchemy/pool/impl.py\", line 143, in _do_get\n",
      "    return self._create_connection()\n",
      "  File \"/home/kelan/.local/lib/python3.10/site-packages/sqlalchemy/pool/base.py\", line 256, in _create_connection\n",
      "    return _ConnectionRecord(self)\n",
      "  File \"/home/kelan/.local/lib/python3.10/site-packages/sqlalchemy/pool/base.py\", line 371, in __init__\n",
      "    self.__connect()\n",
      "  File \"/home/kelan/.local/lib/python3.10/site-packages/sqlalchemy/pool/base.py\", line 665, in __connect\n",
      "    with util.safe_reraise():\n",
      "  File \"/home/kelan/.local/lib/python3.10/site-packages/sqlalchemy/util/langhelpers.py\", line 70, in __exit__\n",
      "    compat.raise_(\n",
      "  File \"/home/kelan/.local/lib/python3.10/site-packages/sqlalchemy/util/compat.py\", line 208, in raise_\n",
      "    raise exception\n",
      "  File \"/home/kelan/.local/lib/python3.10/site-packages/sqlalchemy/pool/base.py\", line 661, in __connect\n",
      "    self.dbapi_connection = connection = pool._invoke_creator(self)\n",
      "  File \"/home/kelan/.local/lib/python3.10/site-packages/sqlalchemy/engine/create.py\", line 578, in connect\n",
      "    return dialect.connect(*cargs, **cparams)\n",
      "  File \"/home/kelan/.local/lib/python3.10/site-packages/sqlalchemy/engine/default.py\", line 597, in connect\n",
      "    return self.dbapi.connect(*cargs, **cparams)\n",
      "  File \"/home/kelan/.local/lib/python3.10/site-packages/psycopg2/__init__.py\", line 122, in connect\n",
      "    conn = _connect(dsn, connection_factory=connection_factory, **kwasync)\n",
      "psycopg2.OperationalError: connection to server at \"localhost\" (127.0.0.1), port 5432 failed: Connection refused\n",
      "\tIs the server running on that host and accepting TCP/IP connections?\n",
      "\n",
      "\n",
      "The above exception was the direct cause of the following exception:\n",
      "\n",
      "Traceback (most recent call last):\n",
      "  File \"/home/kelan/.local/lib/python3.10/site-packages/IPython/core/interactiveshell.py\", line 3398, in run_code\n",
      "    exec(code_obj, self.user_global_ns, self.user_ns)\n",
      "  File \"/tmp/ipykernel_573/3352295283.py\", line 4, in <cell line: 4>\n",
      "    pd.read_sql(query, con=engine)\n",
      "  File \"/home/kelan/.local/lib/python3.10/site-packages/pandas/io/sql.py\", line 592, in read_sql\n",
      "    return pandas_sql.read_query(\n",
      "  File \"/home/kelan/.local/lib/python3.10/site-packages/pandas/io/sql.py\", line 1557, in read_query\n",
      "    result = self.execute(*args)\n",
      "  File \"/home/kelan/.local/lib/python3.10/site-packages/pandas/io/sql.py\", line 1402, in execute\n",
      "    return self.connectable.execution_options().execute(*args, **kwargs)\n",
      "  File \"<string>\", line 2, in execute\n",
      "  File \"/home/kelan/.local/lib/python3.10/site-packages/sqlalchemy/util/deprecations.py\", line 402, in warned\n",
      "    return fn(*args, **kwargs)\n",
      "  File \"/home/kelan/.local/lib/python3.10/site-packages/sqlalchemy/engine/base.py\", line 3256, in execute\n",
      "    connection = self.connect(close_with_result=True)\n",
      "  File \"/home/kelan/.local/lib/python3.10/site-packages/sqlalchemy/engine/base.py\", line 3315, in connect\n",
      "    return self._connection_cls(self, close_with_result=close_with_result)\n",
      "  File \"/home/kelan/.local/lib/python3.10/site-packages/sqlalchemy/engine/base.py\", line 96, in __init__\n",
      "    else engine.raw_connection()\n",
      "  File \"/home/kelan/.local/lib/python3.10/site-packages/sqlalchemy/engine/base.py\", line 3394, in raw_connection\n",
      "    return self._wrap_pool_connect(self.pool.connect, _connection)\n",
      "  File \"/home/kelan/.local/lib/python3.10/site-packages/sqlalchemy/engine/base.py\", line 3364, in _wrap_pool_connect\n",
      "    Connection._handle_dbapi_exception_noconnection(\n",
      "  File \"/home/kelan/.local/lib/python3.10/site-packages/sqlalchemy/engine/base.py\", line 2198, in _handle_dbapi_exception_noconnection\n",
      "    util.raise_(\n",
      "  File \"/home/kelan/.local/lib/python3.10/site-packages/sqlalchemy/util/compat.py\", line 208, in raise_\n",
      "    raise exception\n",
      "  File \"/home/kelan/.local/lib/python3.10/site-packages/sqlalchemy/engine/base.py\", line 3361, in _wrap_pool_connect\n",
      "    return fn()\n",
      "  File \"/home/kelan/.local/lib/python3.10/site-packages/sqlalchemy/pool/base.py\", line 310, in connect\n",
      "    return _ConnectionFairy._checkout(self)\n",
      "  File \"/home/kelan/.local/lib/python3.10/site-packages/sqlalchemy/pool/base.py\", line 868, in _checkout\n",
      "    fairy = _ConnectionRecord.checkout(pool)\n",
      "  File \"/home/kelan/.local/lib/python3.10/site-packages/sqlalchemy/pool/base.py\", line 476, in checkout\n",
      "    rec = pool._do_get()\n",
      "  File \"/home/kelan/.local/lib/python3.10/site-packages/sqlalchemy/pool/impl.py\", line 145, in _do_get\n",
      "    with util.safe_reraise():\n",
      "  File \"/home/kelan/.local/lib/python3.10/site-packages/sqlalchemy/util/langhelpers.py\", line 70, in __exit__\n",
      "    compat.raise_(\n",
      "  File \"/home/kelan/.local/lib/python3.10/site-packages/sqlalchemy/util/compat.py\", line 208, in raise_\n",
      "    raise exception\n",
      "  File \"/home/kelan/.local/lib/python3.10/site-packages/sqlalchemy/pool/impl.py\", line 143, in _do_get\n",
      "    return self._create_connection()\n",
      "  File \"/home/kelan/.local/lib/python3.10/site-packages/sqlalchemy/pool/base.py\", line 256, in _create_connection\n",
      "    return _ConnectionRecord(self)\n",
      "  File \"/home/kelan/.local/lib/python3.10/site-packages/sqlalchemy/pool/base.py\", line 371, in __init__\n",
      "    self.__connect()\n",
      "  File \"/home/kelan/.local/lib/python3.10/site-packages/sqlalchemy/pool/base.py\", line 665, in __connect\n",
      "    with util.safe_reraise():\n",
      "  File \"/home/kelan/.local/lib/python3.10/site-packages/sqlalchemy/util/langhelpers.py\", line 70, in __exit__\n",
      "    compat.raise_(\n",
      "  File \"/home/kelan/.local/lib/python3.10/site-packages/sqlalchemy/util/compat.py\", line 208, in raise_\n",
      "    raise exception\n",
      "  File \"/home/kelan/.local/lib/python3.10/site-packages/sqlalchemy/pool/base.py\", line 661, in __connect\n",
      "    self.dbapi_connection = connection = pool._invoke_creator(self)\n",
      "  File \"/home/kelan/.local/lib/python3.10/site-packages/sqlalchemy/engine/create.py\", line 578, in connect\n",
      "    return dialect.connect(*cargs, **cparams)\n",
      "  File \"/home/kelan/.local/lib/python3.10/site-packages/sqlalchemy/engine/default.py\", line 597, in connect\n",
      "    return self.dbapi.connect(*cargs, **cparams)\n",
      "  File \"/home/kelan/.local/lib/python3.10/site-packages/psycopg2/__init__.py\", line 122, in connect\n",
      "    conn = _connect(dsn, connection_factory=connection_factory, **kwasync)\n",
      "sqlalchemy.exc.OperationalError: (psycopg2.OperationalError) connection to server at \"localhost\" (127.0.0.1), port 5432 failed: Connection refused\n",
      "\tIs the server running on that host and accepting TCP/IP connections?\n",
      "\n",
      "(Background on this error at: https://sqlalche.me/e/14/e3q8)\n",
      "\n",
      "During handling of the above exception, another exception occurred:\n",
      "\n",
      "Traceback (most recent call last):\n",
      "  File \"/home/kelan/.local/lib/python3.10/site-packages/executing/executing.py\", line 312, in executing\n",
      "    args = executing_cache[key]\n",
      "KeyError: (<code object run_code at 0x7f05129140e0, file \"/home/kelan/.local/lib/python3.10/site-packages/IPython/core/interactiveshell.py\", line 3362>, 139659763073248, 76)\n",
      "\n",
      "During handling of the above exception, another exception occurred:\n",
      "\n",
      "Traceback (most recent call last):\n",
      "  File \"/home/kelan/.local/lib/python3.10/site-packages/IPython/core/interactiveshell.py\", line 1993, in showtraceback\n",
      "    stb = self.InteractiveTB.structured_traceback(\n",
      "  File \"/home/kelan/.local/lib/python3.10/site-packages/IPython/core/ultratb.py\", line 1118, in structured_traceback\n",
      "    return FormattedTB.structured_traceback(\n",
      "  File \"/home/kelan/.local/lib/python3.10/site-packages/IPython/core/ultratb.py\", line 1012, in structured_traceback\n",
      "    return VerboseTB.structured_traceback(\n",
      "  File \"/home/kelan/.local/lib/python3.10/site-packages/IPython/core/ultratb.py\", line 865, in structured_traceback\n",
      "    formatted_exception = self.format_exception_as_a_whole(etype, evalue, etb, number_of_lines_of_context,\n",
      "  File \"/home/kelan/.local/lib/python3.10/site-packages/IPython/core/ultratb.py\", line 799, in format_exception_as_a_whole\n",
      "    self.get_records(etb, number_of_lines_of_context, tb_offset) if etb else []\n",
      "  File \"/home/kelan/.local/lib/python3.10/site-packages/IPython/core/ultratb.py\", line 854, in get_records\n",
      "    return list(stack_data.FrameInfo.stack_data(etb, options=options))[tb_offset:]\n",
      "  File \"/home/kelan/.local/lib/python3.10/site-packages/stack_data/core.py\", line 563, in stack_data\n",
      "    yield from collapse_repeated(\n",
      "  File \"/home/kelan/.local/lib/python3.10/site-packages/stack_data/utils.py\", line 84, in collapse_repeated\n",
      "    yield from map(mapper, original_group)\n",
      "  File \"/home/kelan/.local/lib/python3.10/site-packages/stack_data/core.py\", line 553, in mapper\n",
      "    return cls(f, options)\n",
      "  File \"/home/kelan/.local/lib/python3.10/site-packages/stack_data/core.py\", line 518, in __init__\n",
      "    self.executing = Source.executing(frame_or_tb)\n",
      "  File \"/home/kelan/.local/lib/python3.10/site-packages/executing/executing.py\", line 364, in executing\n",
      "    args = find(source=cls.for_frame(frame), retry_cache=True)\n",
      "  File \"/home/kelan/.local/lib/python3.10/site-packages/executing/executing.py\", line 247, in for_frame\n",
      "    return cls.for_filename(frame.f_code.co_filename, frame.f_globals or {}, use_cache)\n",
      "  File \"/home/kelan/.local/lib/python3.10/site-packages/executing/executing.py\", line 265, in for_filename\n",
      "    result = source_cache[filename] = cls._for_filename_and_lines(filename, lines)\n",
      "  File \"/home/kelan/.local/lib/python3.10/site-packages/executing/executing.py\", line 276, in _for_filename_and_lines\n",
      "    result = source_cache[(filename, lines)] = cls(filename, lines)\n",
      "  File \"/home/kelan/.local/lib/python3.10/site-packages/stack_data/core.py\", line 81, in __init__\n",
      "    self.asttokens()\n",
      "  File \"/home/kelan/.local/lib/python3.10/site-packages/executing/executing.py\", line 408, in asttokens\n",
      "    return ASTTokens(\n",
      "  File \"/home/kelan/.local/lib/python3.10/site-packages/asttokens/asttokens.py\", line 61, in __init__\n",
      "    source_text = six.ensure_text(source_text)\n",
      "AttributeError: module 'six' has no attribute 'ensure_text'\n"
     ]
    }
   ],
   "source": [
    "query = \"\"\"\n",
    "SELECT * FROM yellow_taxi_2021_08 LIMIT 100;\n",
    "\"\"\"\n",
    "pd.read_sql(query, con=engine)\n"
   ]
  },
  {
   "cell_type": "code",
   "execution_count": null,
   "id": "773d4d8a",
   "metadata": {},
   "outputs": [],
   "source": []
  }
 ],
 "metadata": {
  "kernelspec": {
   "display_name": "Python 3.10.6 64-bit",
   "language": "python",
   "name": "python3"
  },
  "language_info": {
   "codemirror_mode": {
    "name": "ipython",
    "version": 3
   },
   "file_extension": ".py",
   "mimetype": "text/x-python",
   "name": "python",
   "nbconvert_exporter": "python",
   "pygments_lexer": "ipython3",
   "version": "3.10.6"
  },
  "vscode": {
   "interpreter": {
    "hash": "31f2aee4e71d21fbe5cf8b01ff0e069b9275f58929596ceb00d14d90e3e16cd6"
   }
  }
 },
 "nbformat": 4,
 "nbformat_minor": 5
}
