[2022-09-01 10:49:19,155] {taskinstance.py:1032} INFO - Dependencies all met for <TaskInstance: gcs_2_bq_dag.download_bucket manual__2022-09-01T10:18:52.693683+00:00 [queued]>
[2022-09-01 10:49:19,161] {taskinstance.py:1032} INFO - Dependencies all met for <TaskInstance: gcs_2_bq_dag.download_bucket manual__2022-09-01T10:18:52.693683+00:00 [queued]>
[2022-09-01 10:49:19,161] {taskinstance.py:1238} INFO - 
--------------------------------------------------------------------------------
[2022-09-01 10:49:19,161] {taskinstance.py:1239} INFO - Starting attempt 2 of 2
[2022-09-01 10:49:19,161] {taskinstance.py:1240} INFO - 
--------------------------------------------------------------------------------
[2022-09-01 10:49:19,170] {taskinstance.py:1259} INFO - Executing <Task(BashOperator): download_bucket> on 2022-09-01 10:18:52.693683+00:00
[2022-09-01 10:49:19,174] {standard_task_runner.py:52} INFO - Started process 285 to run task
[2022-09-01 10:49:19,176] {standard_task_runner.py:76} INFO - Running: ['***', 'tasks', 'run', 'gcs_2_bq_dag', 'download_bucket', 'manual__2022-09-01T10:18:52.693683+00:00', '--job-id', '304', '--raw', '--subdir', 'DAGS_FOLDER/gcs_2_bq_dag.py', '--cfg-path', '/tmp/tmp0x518cql', '--error-file', '/tmp/tmp32_ombhg']
[2022-09-01 10:49:19,176] {standard_task_runner.py:77} INFO - Job 304: Subtask download_bucket
[2022-09-01 10:49:19,212] {logging_mixin.py:109} INFO - Running <TaskInstance: gcs_2_bq_dag.download_bucket manual__2022-09-01T10:18:52.693683+00:00 [running]> on host f111e1240143
[2022-09-01 10:49:19,248] {taskinstance.py:1426} INFO - Exporting the following env vars:
AIRFLOW_CTX_DAG_OWNER=***
AIRFLOW_CTX_DAG_ID=gcs_2_bq_dag
AIRFLOW_CTX_TASK_ID=download_bucket
AIRFLOW_CTX_EXECUTION_DATE=2022-09-01T10:18:52.693683+00:00
AIRFLOW_CTX_DAG_RUN_ID=manual__2022-09-01T10:18:52.693683+00:00
[2022-09-01 10:49:19,249] {subprocess.py:62} INFO - Tmp dir root location: 
 /tmp
[2022-09-01 10:49:19,249] {subprocess.py:74} INFO - Running command: ['bash', '-c', 'gsutil cp -r gs://dtc_data_lake_polynomial-land/yellow/ /temp/']
[2022-09-01 10:49:19,257] {subprocess.py:85} INFO - Output:
[2022-09-01 10:49:20,938] {subprocess.py:89} INFO - ServiceException: 401 Anonymous caller does not have storage.objects.get access to the Google Cloud Storage object.
[2022-09-01 10:49:21,140] {subprocess.py:93} INFO - Command exited with return code 1
[2022-09-01 10:49:21,149] {taskinstance.py:1700} ERROR - Task failed with exception
Traceback (most recent call last):
  File "/home/airflow/.local/lib/python3.7/site-packages/airflow/models/taskinstance.py", line 1329, in _run_raw_task
    self._execute_task_with_callbacks(context)
  File "/home/airflow/.local/lib/python3.7/site-packages/airflow/models/taskinstance.py", line 1455, in _execute_task_with_callbacks
    result = self._execute_task(context, self.task)
  File "/home/airflow/.local/lib/python3.7/site-packages/airflow/models/taskinstance.py", line 1511, in _execute_task
    result = execute_callable(context=context)
  File "/home/airflow/.local/lib/python3.7/site-packages/airflow/operators/bash.py", line 188, in execute
    f'Bash command failed. The command returned a non-zero exit code {result.exit_code}.'
airflow.exceptions.AirflowException: Bash command failed. The command returned a non-zero exit code 1.
[2022-09-01 10:49:21,154] {taskinstance.py:1277} INFO - Marking task as FAILED. dag_id=gcs_2_bq_dag, task_id=download_bucket, execution_date=20220901T101852, start_date=20220901T104919, end_date=20220901T104921
[2022-09-01 10:49:21,166] {standard_task_runner.py:92} ERROR - Failed to execute job 304 for task download_bucket
Traceback (most recent call last):
  File "/home/airflow/.local/lib/python3.7/site-packages/airflow/task/task_runner/standard_task_runner.py", line 85, in _start_by_fork
    args.func(args, dag=self.dag)
  File "/home/airflow/.local/lib/python3.7/site-packages/airflow/cli/cli_parser.py", line 48, in command
    return func(*args, **kwargs)
  File "/home/airflow/.local/lib/python3.7/site-packages/airflow/utils/cli.py", line 92, in wrapper
    return f(*args, **kwargs)
  File "/home/airflow/.local/lib/python3.7/site-packages/airflow/cli/commands/task_command.py", line 298, in task_run
    _run_task_by_selected_method(args, dag, ti)
  File "/home/airflow/.local/lib/python3.7/site-packages/airflow/cli/commands/task_command.py", line 107, in _run_task_by_selected_method
    _run_raw_task(args, ti)
  File "/home/airflow/.local/lib/python3.7/site-packages/airflow/cli/commands/task_command.py", line 184, in _run_raw_task
    error_file=args.error_file,
  File "/home/airflow/.local/lib/python3.7/site-packages/airflow/utils/session.py", line 70, in wrapper
    return func(*args, session=session, **kwargs)
  File "/home/airflow/.local/lib/python3.7/site-packages/airflow/models/taskinstance.py", line 1329, in _run_raw_task
    self._execute_task_with_callbacks(context)
  File "/home/airflow/.local/lib/python3.7/site-packages/airflow/models/taskinstance.py", line 1455, in _execute_task_with_callbacks
    result = self._execute_task(context, self.task)
  File "/home/airflow/.local/lib/python3.7/site-packages/airflow/models/taskinstance.py", line 1511, in _execute_task
    result = execute_callable(context=context)
  File "/home/airflow/.local/lib/python3.7/site-packages/airflow/operators/bash.py", line 188, in execute
    f'Bash command failed. The command returned a non-zero exit code {result.exit_code}.'
airflow.exceptions.AirflowException: Bash command failed. The command returned a non-zero exit code 1.
[2022-09-01 10:49:21,193] {local_task_job.py:154} INFO - Task exited with return code 1
[2022-09-01 10:49:21,217] {local_task_job.py:264} INFO - 0 downstream tasks scheduled from follow-on schedule check
