[2022-09-01 10:55:41,335] {taskinstance.py:1032} INFO - Dependencies all met for <TaskInstance: gcs_2_bq_dag.download_bucket manual__2022-09-01T10:18:52.693683+00:00 [queued]>
[2022-09-01 10:55:41,344] {taskinstance.py:1032} INFO - Dependencies all met for <TaskInstance: gcs_2_bq_dag.download_bucket manual__2022-09-01T10:18:52.693683+00:00 [queued]>
[2022-09-01 10:55:41,345] {taskinstance.py:1238} INFO - 
--------------------------------------------------------------------------------
[2022-09-01 10:55:41,345] {taskinstance.py:1239} INFO - Starting attempt 3 of 3
[2022-09-01 10:55:41,345] {taskinstance.py:1240} INFO - 
--------------------------------------------------------------------------------
[2022-09-01 10:55:41,356] {taskinstance.py:1259} INFO - Executing <Task(BashOperator): download_bucket> on 2022-09-01 10:18:52.693683+00:00
[2022-09-01 10:55:41,361] {standard_task_runner.py:52} INFO - Started process 1054 to run task
[2022-09-01 10:55:41,363] {standard_task_runner.py:76} INFO - Running: ['***', 'tasks', 'run', 'gcs_2_bq_dag', 'download_bucket', 'manual__2022-09-01T10:18:52.693683+00:00', '--job-id', '305', '--raw', '--subdir', 'DAGS_FOLDER/gcs_2_bq_dag.py', '--cfg-path', '/tmp/tmpsd7_oxme', '--error-file', '/tmp/tmpghho1v14']
[2022-09-01 10:55:41,364] {standard_task_runner.py:77} INFO - Job 305: Subtask download_bucket
[2022-09-01 10:55:41,410] {logging_mixin.py:109} INFO - Running <TaskInstance: gcs_2_bq_dag.download_bucket manual__2022-09-01T10:18:52.693683+00:00 [running]> on host f111e1240143
[2022-09-01 10:55:41,459] {taskinstance.py:1426} INFO - Exporting the following env vars:
AIRFLOW_CTX_DAG_OWNER=***
AIRFLOW_CTX_DAG_ID=gcs_2_bq_dag
AIRFLOW_CTX_TASK_ID=download_bucket
AIRFLOW_CTX_EXECUTION_DATE=2022-09-01T10:18:52.693683+00:00
AIRFLOW_CTX_DAG_RUN_ID=manual__2022-09-01T10:18:52.693683+00:00
[2022-09-01 10:55:41,460] {subprocess.py:62} INFO - Tmp dir root location: 
 /tmp
[2022-09-01 10:55:41,461] {subprocess.py:74} INFO - Running command: ['bash', '-c', 'gcloud auth activate-service-account --key-file=/.google/credentials.json &&gsutil cp -r gs://dtc_data_lake_polynomial-land/yellow/ /temp/']
[2022-09-01 10:55:41,469] {subprocess.py:85} INFO - Output:
[2022-09-01 10:55:41,771] {subprocess.py:89} INFO - ERROR: (gcloud.auth.activate-service-account) Unable to read file [/.google/credentials.json]: [Errno 2] No such file or directory: '/.google/credentials.json'
[2022-09-01 10:55:41,831] {subprocess.py:93} INFO - Command exited with return code 1
[2022-09-01 10:55:41,841] {taskinstance.py:1700} ERROR - Task failed with exception
Traceback (most recent call last):
  File "/home/airflow/.local/lib/python3.7/site-packages/airflow/models/taskinstance.py", line 1329, in _run_raw_task
    self._execute_task_with_callbacks(context)
  File "/home/airflow/.local/lib/python3.7/site-packages/airflow/models/taskinstance.py", line 1455, in _execute_task_with_callbacks
    result = self._execute_task(context, self.task)
  File "/home/airflow/.local/lib/python3.7/site-packages/airflow/models/taskinstance.py", line 1511, in _execute_task
    result = execute_callable(context=context)
  File "/home/airflow/.local/lib/python3.7/site-packages/airflow/operators/bash.py", line 188, in execute
    f'Bash command failed. The command returned a non-zero exit code {result.exit_code}.'
airflow.exceptions.AirflowException: Bash command failed. The command returned a non-zero exit code 1.
[2022-09-01 10:55:41,846] {taskinstance.py:1277} INFO - Marking task as FAILED. dag_id=gcs_2_bq_dag, task_id=download_bucket, execution_date=20220901T101852, start_date=20220901T105541, end_date=20220901T105541
[2022-09-01 10:55:41,858] {standard_task_runner.py:92} ERROR - Failed to execute job 305 for task download_bucket
Traceback (most recent call last):
  File "/home/airflow/.local/lib/python3.7/site-packages/airflow/task/task_runner/standard_task_runner.py", line 85, in _start_by_fork
    args.func(args, dag=self.dag)
  File "/home/airflow/.local/lib/python3.7/site-packages/airflow/cli/cli_parser.py", line 48, in command
    return func(*args, **kwargs)
  File "/home/airflow/.local/lib/python3.7/site-packages/airflow/utils/cli.py", line 92, in wrapper
    return f(*args, **kwargs)
  File "/home/airflow/.local/lib/python3.7/site-packages/airflow/cli/commands/task_command.py", line 298, in task_run
    _run_task_by_selected_method(args, dag, ti)
  File "/home/airflow/.local/lib/python3.7/site-packages/airflow/cli/commands/task_command.py", line 107, in _run_task_by_selected_method
    _run_raw_task(args, ti)
  File "/home/airflow/.local/lib/python3.7/site-packages/airflow/cli/commands/task_command.py", line 184, in _run_raw_task
    error_file=args.error_file,
  File "/home/airflow/.local/lib/python3.7/site-packages/airflow/utils/session.py", line 70, in wrapper
    return func(*args, session=session, **kwargs)
  File "/home/airflow/.local/lib/python3.7/site-packages/airflow/models/taskinstance.py", line 1329, in _run_raw_task
    self._execute_task_with_callbacks(context)
  File "/home/airflow/.local/lib/python3.7/site-packages/airflow/models/taskinstance.py", line 1455, in _execute_task_with_callbacks
    result = self._execute_task(context, self.task)
  File "/home/airflow/.local/lib/python3.7/site-packages/airflow/models/taskinstance.py", line 1511, in _execute_task
    result = execute_callable(context=context)
  File "/home/airflow/.local/lib/python3.7/site-packages/airflow/operators/bash.py", line 188, in execute
    f'Bash command failed. The command returned a non-zero exit code {result.exit_code}.'
airflow.exceptions.AirflowException: Bash command failed. The command returned a non-zero exit code 1.
[2022-09-01 10:55:41,897] {local_task_job.py:154} INFO - Task exited with return code 1
[2022-09-01 10:55:41,920] {local_task_job.py:264} INFO - 0 downstream tasks scheduled from follow-on schedule check
