[2022-08-31 14:12:41,437] {taskinstance.py:1032} INFO - Dependencies all met for <TaskInstance: green_taxi_data_ingest.download_dataset_task manual__2022-08-31T14:12:40.310871+00:00 [queued]>
[2022-08-31 14:12:41,450] {taskinstance.py:1032} INFO - Dependencies all met for <TaskInstance: green_taxi_data_ingest.download_dataset_task manual__2022-08-31T14:12:40.310871+00:00 [queued]>
[2022-08-31 14:12:41,450] {taskinstance.py:1238} INFO - 
--------------------------------------------------------------------------------
[2022-08-31 14:12:41,450] {taskinstance.py:1239} INFO - Starting attempt 1 of 1
[2022-08-31 14:12:41,450] {taskinstance.py:1240} INFO - 
--------------------------------------------------------------------------------
[2022-08-31 14:12:41,465] {taskinstance.py:1259} INFO - Executing <Task(BashOperator): download_dataset_task> on 2022-08-31 14:12:40.310871+00:00
[2022-08-31 14:12:41,470] {standard_task_runner.py:52} INFO - Started process 3747 to run task
[2022-08-31 14:12:41,473] {standard_task_runner.py:76} INFO - Running: ['***', 'tasks', 'run', 'green_taxi_data_ingest', 'download_dataset_task', 'manual__2022-08-31T14:12:40.310871+00:00', '--job-id', '162', '--raw', '--subdir', 'DAGS_FOLDER/green_taxi_data_ingest_dag.py', '--cfg-path', '/tmp/tmpgclfy52m', '--error-file', '/tmp/tmpgf4x0sgj']
[2022-08-31 14:12:41,475] {standard_task_runner.py:77} INFO - Job 162: Subtask download_dataset_task
[2022-08-31 14:12:41,527] {logging_mixin.py:109} INFO - Running <TaskInstance: green_taxi_data_ingest.download_dataset_task manual__2022-08-31T14:12:40.310871+00:00 [running]> on host 0aad59a5352b
[2022-08-31 14:12:41,563] {warnings.py:110} WARNING - /home/***/.local/lib/python3.7/site-packages/***/utils/context.py:152: AirflowContextDeprecationWarning: Accessing 'execution_date' from the template is deprecated and will be removed in a future version. Please use 'data_interval_start' or 'logical_date' instead.
  warnings.warn(_create_deprecation_warning(key, self._deprecation_replacements[key]))

[2022-08-31 14:12:41,583] {taskinstance.py:1426} INFO - Exporting the following env vars:
AIRFLOW_CTX_DAG_OWNER=***
AIRFLOW_CTX_DAG_ID=green_taxi_data_ingest
AIRFLOW_CTX_TASK_ID=download_dataset_task
AIRFLOW_CTX_EXECUTION_DATE=2022-08-31T14:12:40.310871+00:00
AIRFLOW_CTX_DAG_RUN_ID=manual__2022-08-31T14:12:40.310871+00:00
[2022-08-31 14:12:41,584] {subprocess.py:62} INFO - Tmp dir root location: 
 /tmp
[2022-08-31 14:12:41,585] {subprocess.py:74} INFO - Running command: ['bash', '-c', 'curl -sSLf https://d37ci6vzurychx.cloudfront.net/trip-data/green_tripdata_2022-08.parquet > /opt/***/green_tripdata_2022-08.parquet']
[2022-08-31 14:12:41,593] {subprocess.py:85} INFO - Output:
[2022-08-31 14:12:42,121] {subprocess.py:89} INFO - curl: (22) The requested URL returned error: 403
[2022-08-31 14:12:42,122] {subprocess.py:93} INFO - Command exited with return code 22
[2022-08-31 14:12:42,133] {taskinstance.py:1700} ERROR - Task failed with exception
Traceback (most recent call last):
  File "/home/airflow/.local/lib/python3.7/site-packages/airflow/models/taskinstance.py", line 1329, in _run_raw_task
    self._execute_task_with_callbacks(context)
  File "/home/airflow/.local/lib/python3.7/site-packages/airflow/models/taskinstance.py", line 1455, in _execute_task_with_callbacks
    result = self._execute_task(context, self.task)
  File "/home/airflow/.local/lib/python3.7/site-packages/airflow/models/taskinstance.py", line 1511, in _execute_task
    result = execute_callable(context=context)
  File "/home/airflow/.local/lib/python3.7/site-packages/airflow/operators/bash.py", line 188, in execute
    f'Bash command failed. The command returned a non-zero exit code {result.exit_code}.'
airflow.exceptions.AirflowException: Bash command failed. The command returned a non-zero exit code 22.
[2022-08-31 14:12:42,138] {taskinstance.py:1277} INFO - Marking task as FAILED. dag_id=green_taxi_data_ingest, task_id=download_dataset_task, execution_date=20220831T141240, start_date=20220831T141241, end_date=20220831T141242
[2022-08-31 14:12:42,153] {standard_task_runner.py:92} ERROR - Failed to execute job 162 for task download_dataset_task
Traceback (most recent call last):
  File "/home/airflow/.local/lib/python3.7/site-packages/airflow/task/task_runner/standard_task_runner.py", line 85, in _start_by_fork
    args.func(args, dag=self.dag)
  File "/home/airflow/.local/lib/python3.7/site-packages/airflow/cli/cli_parser.py", line 48, in command
    return func(*args, **kwargs)
  File "/home/airflow/.local/lib/python3.7/site-packages/airflow/utils/cli.py", line 92, in wrapper
    return f(*args, **kwargs)
  File "/home/airflow/.local/lib/python3.7/site-packages/airflow/cli/commands/task_command.py", line 298, in task_run
    _run_task_by_selected_method(args, dag, ti)
  File "/home/airflow/.local/lib/python3.7/site-packages/airflow/cli/commands/task_command.py", line 107, in _run_task_by_selected_method
    _run_raw_task(args, ti)
  File "/home/airflow/.local/lib/python3.7/site-packages/airflow/cli/commands/task_command.py", line 184, in _run_raw_task
    error_file=args.error_file,
  File "/home/airflow/.local/lib/python3.7/site-packages/airflow/utils/session.py", line 70, in wrapper
    return func(*args, session=session, **kwargs)
  File "/home/airflow/.local/lib/python3.7/site-packages/airflow/models/taskinstance.py", line 1329, in _run_raw_task
    self._execute_task_with_callbacks(context)
  File "/home/airflow/.local/lib/python3.7/site-packages/airflow/models/taskinstance.py", line 1455, in _execute_task_with_callbacks
    result = self._execute_task(context, self.task)
  File "/home/airflow/.local/lib/python3.7/site-packages/airflow/models/taskinstance.py", line 1511, in _execute_task
    result = execute_callable(context=context)
  File "/home/airflow/.local/lib/python3.7/site-packages/airflow/operators/bash.py", line 188, in execute
    f'Bash command failed. The command returned a non-zero exit code {result.exit_code}.'
airflow.exceptions.AirflowException: Bash command failed. The command returned a non-zero exit code 22.
[2022-08-31 14:12:42,167] {local_task_job.py:154} INFO - Task exited with return code 1
[2022-08-31 14:12:42,199] {local_task_job.py:264} INFO - 0 downstream tasks scheduled from follow-on schedule check
