[2022-08-31 14:34:27,826] {taskinstance.py:1032} INFO - Dependencies all met for <TaskInstance: green_taxi_data_ingest.download_dataset_task manual__2022-08-31T14:34:26.224159+00:00 [queued]>
[2022-08-31 14:34:27,834] {taskinstance.py:1032} INFO - Dependencies all met for <TaskInstance: green_taxi_data_ingest.download_dataset_task manual__2022-08-31T14:34:26.224159+00:00 [queued]>
[2022-08-31 14:34:27,834] {taskinstance.py:1238} INFO - 
--------------------------------------------------------------------------------
[2022-08-31 14:34:27,835] {taskinstance.py:1239} INFO - Starting attempt 1 of 1
[2022-08-31 14:34:27,835] {taskinstance.py:1240} INFO - 
--------------------------------------------------------------------------------
[2022-08-31 14:34:27,848] {taskinstance.py:1259} INFO - Executing <Task(BashOperator): download_dataset_task> on 2022-08-31 14:34:26.224159+00:00
[2022-08-31 14:34:27,855] {standard_task_runner.py:52} INFO - Started process 4833 to run task
[2022-08-31 14:34:27,858] {standard_task_runner.py:76} INFO - Running: ['***', 'tasks', 'run', 'green_taxi_data_ingest', 'download_dataset_task', 'manual__2022-08-31T14:34:26.224159+00:00', '--job-id', '177', '--raw', '--subdir', 'DAGS_FOLDER/green_taxi_data_ingest_dag.py', '--cfg-path', '/tmp/tmp07jul821', '--error-file', '/tmp/tmp8ha2si7f']
[2022-08-31 14:34:27,858] {standard_task_runner.py:77} INFO - Job 177: Subtask download_dataset_task
[2022-08-31 14:34:27,908] {logging_mixin.py:109} INFO - Running <TaskInstance: green_taxi_data_ingest.download_dataset_task manual__2022-08-31T14:34:26.224159+00:00 [running]> on host 0aad59a5352b
[2022-08-31 14:34:27,939] {taskinstance.py:1700} ERROR - Task failed with exception
Traceback (most recent call last):
  File "/home/airflow/.local/lib/python3.7/site-packages/airflow/models/taskinstance.py", line 1329, in _run_raw_task
    self._execute_task_with_callbacks(context)
  File "/home/airflow/.local/lib/python3.7/site-packages/airflow/models/taskinstance.py", line 1418, in _execute_task_with_callbacks
    self.render_templates(context=context)
  File "/home/airflow/.local/lib/python3.7/site-packages/airflow/models/taskinstance.py", line 1992, in render_templates
    self.task.render_template_fields(context)
  File "/home/airflow/.local/lib/python3.7/site-packages/airflow/models/baseoperator.py", line 1061, in render_template_fields
    self._do_render_template_fields(self, self.template_fields, context, jinja_env, set())
  File "/home/airflow/.local/lib/python3.7/site-packages/airflow/models/baseoperator.py", line 1074, in _do_render_template_fields
    rendered_content = self.render_template(content, context, jinja_env, seen_oids)
  File "/home/airflow/.local/lib/python3.7/site-packages/airflow/models/baseoperator.py", line 1113, in render_template
    return render_template_to_string(template, context)
  File "/home/airflow/.local/lib/python3.7/site-packages/airflow/utils/helpers.py", line 268, in render_template_to_string
    return render_template(template, context, native=False)
  File "/home/airflow/.local/lib/python3.7/site-packages/airflow/utils/helpers.py", line 263, in render_template
    return "".join(nodes)
  File "<template>", line 13, in root
  File "/home/airflow/.local/lib/python3.7/site-packages/jinja2/runtime.py", line 903, in _fail_with_undefined_error
    raise self._undefined_exception(self._undefined_message)
jinja2.exceptions.UndefinedError: 'dict object' has no attribute 'date'
[2022-08-31 14:34:27,951] {taskinstance.py:1277} INFO - Marking task as FAILED. dag_id=green_taxi_data_ingest, task_id=download_dataset_task, execution_date=20220831T143426, start_date=20220831T143427, end_date=20220831T143427
[2022-08-31 14:34:27,963] {standard_task_runner.py:92} ERROR - Failed to execute job 177 for task download_dataset_task
Traceback (most recent call last):
  File "/home/airflow/.local/lib/python3.7/site-packages/airflow/task/task_runner/standard_task_runner.py", line 85, in _start_by_fork
    args.func(args, dag=self.dag)
  File "/home/airflow/.local/lib/python3.7/site-packages/airflow/cli/cli_parser.py", line 48, in command
    return func(*args, **kwargs)
  File "/home/airflow/.local/lib/python3.7/site-packages/airflow/utils/cli.py", line 92, in wrapper
    return f(*args, **kwargs)
  File "/home/airflow/.local/lib/python3.7/site-packages/airflow/cli/commands/task_command.py", line 298, in task_run
    _run_task_by_selected_method(args, dag, ti)
  File "/home/airflow/.local/lib/python3.7/site-packages/airflow/cli/commands/task_command.py", line 107, in _run_task_by_selected_method
    _run_raw_task(args, ti)
  File "/home/airflow/.local/lib/python3.7/site-packages/airflow/cli/commands/task_command.py", line 184, in _run_raw_task
    error_file=args.error_file,
  File "/home/airflow/.local/lib/python3.7/site-packages/airflow/utils/session.py", line 70, in wrapper
    return func(*args, session=session, **kwargs)
  File "/home/airflow/.local/lib/python3.7/site-packages/airflow/models/taskinstance.py", line 1329, in _run_raw_task
    self._execute_task_with_callbacks(context)
  File "/home/airflow/.local/lib/python3.7/site-packages/airflow/models/taskinstance.py", line 1418, in _execute_task_with_callbacks
    self.render_templates(context=context)
  File "/home/airflow/.local/lib/python3.7/site-packages/airflow/models/taskinstance.py", line 1992, in render_templates
    self.task.render_template_fields(context)
  File "/home/airflow/.local/lib/python3.7/site-packages/airflow/models/baseoperator.py", line 1061, in render_template_fields
    self._do_render_template_fields(self, self.template_fields, context, jinja_env, set())
  File "/home/airflow/.local/lib/python3.7/site-packages/airflow/models/baseoperator.py", line 1074, in _do_render_template_fields
    rendered_content = self.render_template(content, context, jinja_env, seen_oids)
  File "/home/airflow/.local/lib/python3.7/site-packages/airflow/models/baseoperator.py", line 1113, in render_template
    return render_template_to_string(template, context)
  File "/home/airflow/.local/lib/python3.7/site-packages/airflow/utils/helpers.py", line 268, in render_template_to_string
    return render_template(template, context, native=False)
  File "/home/airflow/.local/lib/python3.7/site-packages/airflow/utils/helpers.py", line 263, in render_template
    return "".join(nodes)
  File "<template>", line 13, in root
  File "/home/airflow/.local/lib/python3.7/site-packages/jinja2/runtime.py", line 903, in _fail_with_undefined_error
    raise self._undefined_exception(self._undefined_message)
jinja2.exceptions.UndefinedError: 'dict object' has no attribute 'date'
[2022-08-31 14:34:27,989] {local_task_job.py:154} INFO - Task exited with return code 1
[2022-08-31 14:34:28,020] {local_task_job.py:264} INFO - 0 downstream tasks scheduled from follow-on schedule check
